<?xml version="1.0"?>
<robot xmlns:xacro="http://www.ros.org/wiki/xacro" >

    <xacro:include filename="inertial_macros.xacro"/>

    <material name="white">
        <color rgba="1 1 1 1" />
    </material>

    <material name="orange">
        <color rgba="1 0.3 0.1 1"/>
    </material>

    <material name="blue">
        <color rgba="0.2 0.2 1 1"/>
    </material>

    <material name="black">
        <color rgba="0 0 0 1"/>
    </material>

    <!-- BASE LINK -->

    <link name="base_link">

    </link>


    <!-- CHASSIS LINK -->

    <joint name="chassis_joint" type="fixed">
        <parent link="base_link"/>
        <child link="chassis"/>
        <origin xyz="-0.1 0 0"/>
    </joint>

    <link name="chassis">
        <visual>
            <origin xyz="0 0 1"/>
            <geometry>
                <box size="1.5 1 0.02"/>
            </geometry>
            <material name="orange"/>
        </visual>
        <collision>
            <origin xyz="0 0 1"/>
            <geometry>
                <box size="1.5 1 0.02"/>
            </geometry>
        </collision>
        <xacro:inertial_box mass="5" x="1.5" y="1" z="0.02">
            <origin xyz="0 0 0" rpy="0 0 0"/>
        </xacro:inertial_box>
    </link>

    <gazebo reference="chassis">
        <material>Gazebo/orange</material>
    </gazebo>

    <!-- leg_back left  link-->
    
    <joint name="back_leg_joint_1" type="fixed">
        <parent link="chassis"/>
        <child link="b_leg_1"/>
        <origin xyz="0.70 0.45 0.3"/>
    </joint>
    
    <link name="b_leg_1">
        <visual>
            <origin xyz="0 0 0.35"/>
            <geometry>
                <box size="0.05 0.05 0.7"/>
            </geometry>
            <material name="white"/>
        </visual>
        <collision>
            <origin xyz="0 0 0.35"/>
            <geometry>
                <box size="0.05 0.05 0.7"/>
            </geometry>
        </collision>
        <xacro:inertial_box mass="1" x="0.05" y="0.05" z="1">
            <origin xyz="0 0 0" rpy="0 0 0"/>
        </xacro:inertial_box>
    </link>
    
    <!-- leg_back right  link-->
    
    <joint name="back_leg_joint_2" type="fixed">
        <parent link="chassis"/>
        <child link="b_leg_2"/>
        <origin xyz="0.70 -0.45 0.3"/>
    </joint>
    
    <link name="b_leg_2">
        <visual>
            <origin xyz="0 0 0.35"/>
            <geometry>
                <box size="0.05 0.05 0.7"/>
            </geometry>
            <material name="white"/>
        </visual>
        <collision>
            <origin xyz="0 0 0.35"/>
            <geometry>
                <box size="0.05 0.05 0.7"/>
            </geometry>
        </collision>
        <xacro:inertial_box mass="1" x="0.05" y="0.05" z="1">
            <origin xyz="0 0 0" rpy="0 0 0"/>
        </xacro:inertial_box>
    </link>
    
    
    <!-- leg_front left  link-->
    
    <joint name="front_leg_joint_1" type="fixed">
        <parent link="chassis"/>
        <child link="f_leg_1"/>
        <origin xyz="-0.70 -0.45 0.3"/>
    </joint>
    
    <link name="f_leg_1">
        <visual>
            <origin xyz="0 0 0.35"/>
            <geometry>
                <box size="0.05 0.05 0.7"/>
            </geometry>
            <material name="white"/>
        </visual>
        <collision>
            <origin xyz="0 0 0.35"/>
            <geometry>
                <box size="0.05 0.05 0.7"/>
            </geometry>
        </collision>
        <xacro:inertial_box mass="1" x="0.05" y="0.05" z="1">
            <origin xyz="0 0 0" rpy="0 0 0"/>
        </xacro:inertial_box>
    </link>
    
    <!-- leg_front right  link-->
    
    <joint name="front_leg_joint_2" type="fixed">
        <parent link="chassis"/>
        <child link="f_leg_2"/>
        <origin xyz="-0.70 0.45 0.3"/>
    </joint>
    
    <link name="f_leg_2">
        <visual>
            <origin xyz="0 0 0.35"/>
            <geometry>
                <box size="0.05 0.05 0.7"/>
            </geometry>
            <material name="white"/>
        </visual>
        <collision>
            <origin xyz="0 0 0.35"/>
            <geometry>
                <box size="0.05 0.05 0.7"/>
            </geometry>
        </collision>
        <xacro:inertial_box mass="1" x="0.05" y="0.05" z="1">
            <origin xyz="0 0 0" rpy="0 0 0"/>
        </xacro:inertial_box>
    </link>
    
    
    <!-- base_rod 1  link-->
    
    <joint name="base_rod_1_joint" type="fixed">
        <parent link="b_leg_1"/>
        <child link="base_rod_1"/>
        <origin xyz="0.025 0.025 0.05"/>
    </joint>
    
    <link name="base_rod_1">
        <visual>
            <origin xyz="-0.7 -0.025 0"/>
            <geometry>
                <box size="1.4 0.05 0.05"/>
            </geometry>
            <material name="white"/>
        </visual>
        <collision>
            <origin xyz="-0.7 -0.025 0"/>
            <geometry>
                <box size="1.4 0.05 0.05"/>
            </geometry>
        </collision>
        <xacro:inertial_box mass="1" x="1.4" y="0.05" z="0.05">
            <origin xyz="0 0 0" rpy="0 0 0"/>
        </xacro:inertial_box>
    </link>
    
    <!-- base_rod 2  link-->
    
    <joint name="base_rod_2_joint" type="fixed">
        <parent link="b_leg_2"/>
        <child link="base_rod_2"/>
        <origin xyz="0.025 0.025 0.05"/>
    </joint>
    
    <link name="base_rod_2">
        <visual>
            <origin xyz="-0.7 -0.025 0"/>
            <geometry>
                <box size="1.4 0.05 0.05"/>
            </geometry>
            <material name="white"/>
        </visual>
        <collision>
            <origin xyz="-0.7 -0.025 0"/>
            <geometry>
                <box size="1.4 0.05 0.05"/>
            </geometry>
        </collision>
        <xacro:inertial_box mass="1" x="1.4" y="0.05" z="0.05">
            <origin xyz="0 0 0" rpy="0 0 0"/>
        </xacro:inertial_box>
    </link>
    
    <!-- base_rod 3  link-->
    
    <joint name="base_rod_3_joint" type="fixed">
        <parent link="b_leg_1"/>
        <child link="base_rod_3"/>
        <origin xyz="0.025 0.025 0.05"/>
    </joint>
    
    <link name="base_rod_3">
        <visual>
            <origin xyz="-0.025 -0.45 0"/>
            <geometry>
                <box size="0.05 0.9 0.05"/>
            </geometry>
            <material name="white"/>
        </visual>
        <collision>
            <origin xyz="-0.025 -0.45 0"/>
            <geometry>
                <box size="0.05 0.9 0.05"/>
            </geometry>
        </collision>
        <xacro:inertial_box mass="1" x="0.05" y="0.9" z="0.05">
            <origin xyz="0 0 0" rpy="0 0 0"/>
        </xacro:inertial_box>
    </link>
    
    
    
    <!-- base_rod 4  link-->
    
    <joint name="base_rod_4_joint" type="fixed">
        <parent link="f_leg_2"/>
        <child link="base_rod_4"/>
        <origin xyz="0.025 0.025 0.05"/>
    </joint>
    
    <link name="base_rod_4">
        <visual>
            <origin xyz="-0.025 -0.45 0"/>
            <geometry>
                <box size="0.05 0.9 0.05"/>
            </geometry>
            <material name="white"/>
        </visual>
        <collision>
            <origin xyz="-0.025 -0.45 0"/>
            <geometry>
                <box size="0.05 0.9 0.05"/>
            </geometry>
        </collision>
        <xacro:inertial_box mass="1" x="0.05" y="0.9" z="0.05">
            <origin xyz="0 0 0" rpy="0 0 0"/>
        </xacro:inertial_box>
    </link>
    
    
    
    
    <!-- LEFT WHEEL LINK -->
	
    <joint name="left_wheel_joint" type="continuous">
        <parent link="base_link"/>
        <child link="left_wheel"/>
        <origin xyz="0.6 0.52 0.2" rpy="-${pi/2} 0 0" />
        <axis xyz="0 0 1"/>
    </joint>

    <link name="left_wheel">
        <visual>
            <geometry>
                <cylinder radius="0.15" length="0.08"/>
            </geometry>
            <material name="blue"/>
        </visual>
        <collision>
            <geometry>
                <cylinder radius="0.15" length="0.08"/>
            </geometry>
        </collision>
        <xacro:inertial_cylinder mass="1" length="0.15" radius="0.08">
            <origin xyz="0 0 0" rpy="0 0 0"/>
        </xacro:inertial_cylinder>
    </link>

    <gazebo reference="left_wheel">
        <material>Gazebo/Blue</material>
    </gazebo>




    <!-- RIGHT WHEEL LINK -->

    <joint name="right_wheel_joint" type="continuous">
        <parent link="base_link"/>
        <child link="right_wheel"/>
        <origin xyz="0.6 -0.52 0.2" rpy="${pi/2} 0 0" />
        <axis xyz="0 0 -1"/>
    </joint>

    <link name="right_wheel">
        <visual>
            <geometry>
                <cylinder radius="0.15" length="0.08"/>
            </geometry>
            <material name="blue"/>
        </visual>
        <collision>
            <geometry>
                <cylinder radius="0.15" length="0.08"/>
            </geometry>
        </collision>
        <xacro:inertial_cylinder mass="1" length="0.15" radius="0.08">
            <origin xyz="0 0 0" rpy="0 0 0"/>
        </xacro:inertial_cylinder>
    </link>

    <gazebo reference="right_wheel">
        <material>Gazebo/Blue</material>
    </gazebo>


    <!-- CASTER WHEEL 1 LINK -->

    <joint name="caster_wheel_joint1" type="fixed">
        <parent link="chassis"/>
        <child link="caster_wheel1"/>
        <origin xyz="-0.7 0.45 0.15"/>
    </joint>


    <link name="caster_wheel1">
        <visual>
            <geometry>
                <sphere radius="0.1"/>
            </geometry>
            <material name="black"/>
        </visual>
        <collision>
            <geometry>
                <sphere radius="0.1"/>
            </geometry>
        </collision>
        <xacro:inertial_sphere mass="0.2" radius="0.1">
            <origin xyz="0 0 0" rpy="0 0 0"/>
        </xacro:inertial_sphere>
    </link>

    <gazebo reference="caster_wheel1">
        <material>Gazebo/Black</material>
        <mu1 value="0.001"/>
        <mu2 value="0.001"/>
    </gazebo>
    
    <!-- CASTER WHEEL 2 LINK -->

    <joint name="caster_wheel_joint2" type="fixed">
        <parent link="chassis"/>
        <child link="caster_wheel2"/>
        <origin xyz="-0.7 -0.45 0.15"/>
    </joint>


    <link name="caster_wheel2">
        <visual>
            <geometry>
                <sphere radius="0.1"/>
            </geometry>
            <material name="black"/>
        </visual>
        <collision>
            <geometry>
                <sphere radius="0.1"/>
            </geometry>
        </collision>
        <xacro:inertial_sphere mass="0.2" radius="0.1">
            <origin xyz="0 0 0" rpy="0 0 0"/>
        </xacro:inertial_sphere>
    </link>

    <gazebo reference="caster_wheel2">
        <material>Gazebo/Black</material>
        <mu1 value="0.001"/>
        <mu2 value="0.001"/>
    </gazebo>
    
        <!-- CAMERA LINK 1 -->
    
     <joint name="camera_joint1" type="fixed">
        <origin xyz="0.8 0 0.94" rpy="0 0 0"/>
        <parent link="chassis"/>
        <child link="camera_link1"/>        
    </joint>


    <link name="camera_link1">
        <visual>
            <origin xyz="-0.03 0 0" rpy="0 0 0"/>
            <geometry>
                <box size="0.06 0.15 0.15" />
            </geometry>
            <material name="white" />
        </visual>
        <visual>
            <origin xyz="0.03 0 0" rpy="0 ${pi/2} 0"/>
            <geometry>
                <cylinder length="0.06" radius="0.04" />
            </geometry>
            <material name="blue" />
        </visual>
        <collision>
            <origin xyz="0.0 0 0" rpy="0 0 0"/>
            <geometry>
                <box size="0.12 0.15 0.15" />
            </geometry>
        </collision>
        <xacro:inertial_box mass="0.1" x="0.12" y="0.15" z="0.15">
            <origin xyz="0.0 0 0" rpy="0 0 0"/>
        </xacro:inertial_box>
    </link>
    
     <joint name="camera_optical_joint1" type="fixed">
        <origin xyz="0 0 0" rpy="-1.571 0 -1.571" />
        <parent link="camera_link1" />
        <child link="camera_link_optical1" />
    </joint>

    <link name="camera_link_optical1"></link>


    

    <gazebo reference="camera_link1">
        <sensor type="depth" name="my_camera1">
            <update_rate>20</update_rate>
            <visualize>true</visualize>
            <camera name="cam">
                <horizontal_fov>1.3962634</horizontal_fov>
                <image>
                    <width>640</width>
                    <height>480</height>
                    <format>R8B8G8</format>
                </image>
                <clip>
                    <near>0.02</near>
                    <far>300</far>
                </clip>
                <noise>
                    <type>gaussian</type>
                    <mean>0.0</mean>
                    <stddev>0.007</stddev>
                </noise>
            </camera>
            <plugin name="camera_controller1" filename="libgazebo_ros_camera.so">
                <frame_name>camera_link_optical</frame_name>
                <min_depth>0.1</min_depth>
                <max_depth>500</max_depth>
            </plugin>
        </sensor>
    </gazebo>
    
            <!-- CAMERA LINK 2 -->
    
     <joint name="camera_joint2" type="fixed">
        <origin xyz="-0.8 0 0.94" rpy="${pi} -${pi} 0"/>
        <parent link="chassis"/>
        <child link="camera_link2"/>        
    </joint>


    <link name="camera_link2">
        <visual>
            <origin xyz="-0.03 0 0" rpy="0 0 0"/>
            <geometry>
                <box size="0.06 0.15 0.15" />
            </geometry>
            <material name="white" />
        </visual>
        <visual>
            <origin xyz="0.03 0 0" rpy="0 ${pi/2} 0"/>
            <geometry>
                <cylinder length="0.06" radius="0.04" />
            </geometry>
            <material name="blue" />
        </visual>
        <collision>
            <origin xyz="0.0 0 0" rpy="0 0 0"/>
            <geometry>
                <box size="0.12 0.15 0.15" />
            </geometry>
        </collision>
        <xacro:inertial_box mass="0.1" x="0.12" y="0.15" z="0.15">
            <origin xyz="0.0 0 0" rpy="0 0 0"/>
        </xacro:inertial_box>
    </link>
    
     <joint name="camera_optical_joint2" type="fixed">
        <origin xyz="0 0 0" rpy="-1.571 0 -1.571" />
        <parent link="camera_link2" />
        <child link="camera_link_optical2" />
    </joint>

    <link name="camera_link_optical2"></link>


    

    <gazebo reference="camera_link2">
        <sensor type="depth" name="my_camera2">
            <update_rate>20</update_rate>
            <visualize>true</visualize>
            <camera name="cam">
                <horizontal_fov>1.3962634</horizontal_fov>
                <image>
                    <width>640</width>
                    <height>480</height>
                    <format>R8B8G8</format>
                </image>
                <clip>
                    <near>0.02</near>
                    <far>300</far>
                </clip>
                <noise>
                    <type>gaussian</type>
                    <mean>0.0</mean>
                    <stddev>0.007</stddev>
                </noise>
            </camera>
            <plugin name="camera_controller2" filename="libgazebo_ros_camera.so">
                <frame_name>camera_link_optical</frame_name>
                <min_depth>0.1</min_depth>
                <max_depth>500</max_depth>
            </plugin>
        </sensor>
    </gazebo>
    
            <!-- CAMERA LINK 3 -->
    
     <joint name="camera_joint3" type="fixed">
        <origin xyz="0 0 0.94" rpy="0 ${pi/2} 0"/>
        <parent link="chassis"/>
        <child link="camera_link3"/>        
    </joint>


    <link name="camera_link3">
        <visual>
            <origin xyz="-0.03 0 0" rpy="0 0 0"/>
            <geometry>
                <box size="0.06 0.15 0.15" />
            </geometry>
            <material name="white" />
        </visual>
        <visual>
            <origin xyz="0.03 0 0" rpy="0 ${pi/2} 0"/>
            <geometry>
                <cylinder length="0.06" radius="0.04" />
            </geometry>
            <material name="blue" />
        </visual>
        <collision>
            <origin xyz="0.0 0 0" rpy="0 0 0"/>
            <geometry>
                <box size="0.12 0.15 0.15" />
            </geometry>
        </collision>
        <xacro:inertial_box mass="0.1" x="0.12" y="0.15" z="0.15">
            <origin xyz="0.0 0 0" rpy="0 0 0"/>
        </xacro:inertial_box>
    </link>
    
     <joint name="camera_optical_joint3" type="fixed">
        <origin xyz="0 0 0" rpy="-1.571 0 -1.571" />
        <parent link="camera_link3" />
        <child link="camera_link_optical3" />
    </joint>

    <link name="camera_link_optical3"></link>


    

    <gazebo reference="camera_link3">
        <sensor type="depth" name="my_camera3">
            <update_rate>20</update_rate>
            <visualize>true</visualize>
            <camera name="cam">
                <horizontal_fov>1.3962634</horizontal_fov>
                <image>
                    <width>640</width>
                    <height>480</height>
                    <format>R8B8G8</format>
                </image>
                <clip>
                    <near>0.02</near>
                    <far>300</far>
                </clip>
                <noise>
                    <type>gaussian</type>
                    <mean>0.0</mean>
                    <stddev>0.007</stddev>
                </noise>
            </camera>
            <plugin name="camera_controller3" filename="libgazebo_ros_camera.so">
                <frame_name>camera_link_optical</frame_name>
                <min_depth>0.1</min_depth>
                <max_depth>500</max_depth>
            </plugin>
        </sensor>
    </gazebo>

   	

</robot>

   	



  

